[2024-08-05T02:20:01.942+0000] {local_task_job_runner.py:120} INFO - ::group::Pre task execution logs
[2024-08-05T02:20:01.966+0000] {taskinstance.py:2076} INFO - Dependencies all met for dep_context=non-requeueable deps ti=<TaskInstance: csv_to_postgres.load_csv_to_postgres scheduled__2024-08-04T00:00:00+00:00 [queued]>
[2024-08-05T02:20:01.978+0000] {taskinstance.py:2076} INFO - Dependencies all met for dep_context=requeueable deps ti=<TaskInstance: csv_to_postgres.load_csv_to_postgres scheduled__2024-08-04T00:00:00+00:00 [queued]>
[2024-08-05T02:20:01.978+0000] {taskinstance.py:2306} INFO - Starting attempt 2 of 2
[2024-08-05T02:20:02.001+0000] {taskinstance.py:2330} INFO - Executing <Task(PythonOperator): load_csv_to_postgres> on 2024-08-04 00:00:00+00:00
[2024-08-05T02:20:02.008+0000] {warnings.py:112} WARNING - /home/***/.local/lib/python3.12/site-packages/***/task/task_runner/standard_task_runner.py:62: DeprecationWarning: This process (pid=62) is multi-threaded, use of fork() may lead to deadlocks in the child.
  pid = os.fork()

[2024-08-05T02:20:02.010+0000] {standard_task_runner.py:64} INFO - Started process 64 to run task
[2024-08-05T02:20:02.010+0000] {standard_task_runner.py:90} INFO - Running: ['***', 'tasks', 'run', 'csv_to_postgres', 'load_csv_to_postgres', 'scheduled__2024-08-04T00:00:00+00:00', '--job-id', '176', '--raw', '--subdir', 'DAGS_FOLDER/csv.py', '--cfg-path', '/tmp/tmpm_yv354i']
[2024-08-05T02:20:02.011+0000] {standard_task_runner.py:91} INFO - Job 176: Subtask load_csv_to_postgres
[2024-08-05T02:20:02.053+0000] {task_command.py:426} INFO - Running <TaskInstance: csv_to_postgres.load_csv_to_postgres scheduled__2024-08-04T00:00:00+00:00 [running]> on host bd99345677b7
[2024-08-05T02:20:02.138+0000] {taskinstance.py:2648} INFO - Exporting env vars: AIRFLOW_CTX_DAG_OWNER='***' AIRFLOW_CTX_DAG_ID='csv_to_postgres' AIRFLOW_CTX_TASK_ID='load_csv_to_postgres' AIRFLOW_CTX_EXECUTION_DATE='2024-08-04T00:00:00+00:00' AIRFLOW_CTX_TRY_NUMBER='2' AIRFLOW_CTX_DAG_RUN_ID='scheduled__2024-08-04T00:00:00+00:00'
[2024-08-05T02:20:02.145+0000] {taskinstance.py:430} INFO - ::endgroup::
[2024-08-05T02:20:02.154+0000] {base.py:84} INFO - Using connection ID 'postgres' for task execution.
[2024-08-05T02:20:23.207+0000] {taskinstance.py:441} INFO - ::group::Post task execution logs
[2024-08-05T02:20:23.210+0000] {taskinstance.py:2905} ERROR - Task failed with exception
Traceback (most recent call last):
  File "/home/airflow/.local/lib/python3.12/site-packages/airflow/models/taskinstance.py", line 465, in _execute_task
    result = _execute_callable(context=context, **execute_callable_kwargs)
             ^^^^^^^^^^^^^^^^^^^^^^^^^^^^^^^^^^^^^^^^^^^^^^^^^^^^^^^^^^^^^
  File "/home/airflow/.local/lib/python3.12/site-packages/airflow/models/taskinstance.py", line 432, in _execute_callable
    return execute_callable(context=context, **execute_callable_kwargs)
           ^^^^^^^^^^^^^^^^^^^^^^^^^^^^^^^^^^^^^^^^^^^^^^^^^^^^^^^^^^^^
  File "/home/airflow/.local/lib/python3.12/site-packages/airflow/models/baseoperator.py", line 401, in wrapper
    return func(self, *args, **kwargs)
           ^^^^^^^^^^^^^^^^^^^^^^^^^^^
  File "/home/airflow/.local/lib/python3.12/site-packages/airflow/operators/python.py", line 235, in execute
    return_value = self.execute_callable()
                   ^^^^^^^^^^^^^^^^^^^^^^^
  File "/home/airflow/.local/lib/python3.12/site-packages/airflow/operators/python.py", line 252, in execute_callable
    return self.python_callable(*self.op_args, **self.op_kwargs)
           ^^^^^^^^^^^^^^^^^^^^^^^^^^^^^^^^^^^^^^^^^^^^^^^^^^^^^
  File "/opt/airflow/dags/csv.py", line 32, in load_csv_to_postgres
    conn = pg_hook.get_conn()
           ^^^^^^^^^^^^^^^^^^
  File "/home/airflow/.local/lib/python3.12/site-packages/airflow/providers/postgres/hooks/postgres.py", line 175, in get_conn
    self.conn = psycopg2.connect(**conn_args)
                ^^^^^^^^^^^^^^^^^^^^^^^^^^^^^
  File "/home/airflow/.local/lib/python3.12/site-packages/psycopg2/__init__.py", line 122, in connect
    conn = _connect(dsn, connection_factory=connection_factory, **kwasync)
           ^^^^^^^^^^^^^^^^^^^^^^^^^^^^^^^^^^^^^^^^^^^^^^^^^^^^^^^^^^^^^^^
psycopg2.OperationalError: connection to server at "172.19.0.3", port 5432 failed: Connection refused
	Is the server running on that host and accepting TCP/IP connections?

[2024-08-05T02:20:23.224+0000] {taskinstance.py:1206} INFO - Marking task as FAILED. dag_id=csv_to_postgres, task_id=load_csv_to_postgres, run_id=scheduled__2024-08-04T00:00:00+00:00, execution_date=20240804T000000, start_date=20240805T022001, end_date=20240805T022023
[2024-08-05T02:20:23.238+0000] {standard_task_runner.py:110} ERROR - Failed to execute job 176 for task load_csv_to_postgres (connection to server at "172.19.0.3", port 5432 failed: Connection refused
	Is the server running on that host and accepting TCP/IP connections?
; 64)
[2024-08-05T02:20:23.256+0000] {local_task_job_runner.py:243} INFO - Task exited with return code 1
[2024-08-05T02:20:23.269+0000] {taskinstance.py:3503} INFO - 0 downstream tasks scheduled from follow-on schedule check
[2024-08-05T02:20:23.273+0000] {local_task_job_runner.py:222} INFO - ::endgroup::
