[2024-08-02T07:39:59.021+0000] {local_task_job_runner.py:120} INFO - ::group::Pre task execution logs
[2024-08-02T07:39:59.064+0000] {taskinstance.py:2076} INFO - Dependencies all met for dep_context=non-requeueable deps ti=<TaskInstance: csv_to_postgres.load_csv_to_postgres manual__2024-08-02T07:39:53.658874+00:00 [queued]>
[2024-08-02T07:39:59.082+0000] {taskinstance.py:2076} INFO - Dependencies all met for dep_context=requeueable deps ti=<TaskInstance: csv_to_postgres.load_csv_to_postgres manual__2024-08-02T07:39:53.658874+00:00 [queued]>
[2024-08-02T07:39:59.084+0000] {taskinstance.py:2306} INFO - Starting attempt 1 of 2
[2024-08-02T07:39:59.114+0000] {taskinstance.py:2330} INFO - Executing <Task(PythonOperator): load_csv_to_postgres> on 2024-08-02 07:39:53.658874+00:00
[2024-08-02T07:39:59.124+0000] {warnings.py:112} WARNING - /home/***/.local/lib/python3.12/site-packages/***/task/task_runner/standard_task_runner.py:62: DeprecationWarning: This process (pid=119) is multi-threaded, use of fork() may lead to deadlocks in the child.
  pid = os.fork()

[2024-08-02T07:39:59.129+0000] {standard_task_runner.py:90} INFO - Running: ['***', 'tasks', 'run', 'csv_to_postgres', 'load_csv_to_postgres', 'manual__2024-08-02T07:39:53.658874+00:00', '--job-id', '159', '--raw', '--subdir', 'DAGS_FOLDER/ggsheet1.py', '--cfg-path', '/tmp/tmpbvv5sjji']
[2024-08-02T07:39:59.131+0000] {standard_task_runner.py:64} INFO - Started process 121 to run task
[2024-08-02T07:39:59.133+0000] {standard_task_runner.py:91} INFO - Job 159: Subtask load_csv_to_postgres
[2024-08-02T07:39:59.534+0000] {task_command.py:426} INFO - Running <TaskInstance: csv_to_postgres.load_csv_to_postgres manual__2024-08-02T07:39:53.658874+00:00 [running]> on host a401ce1833f7
[2024-08-02T07:39:59.828+0000] {taskinstance.py:2648} INFO - Exporting env vars: AIRFLOW_CTX_DAG_OWNER='***' AIRFLOW_CTX_DAG_ID='csv_to_postgres' AIRFLOW_CTX_TASK_ID='load_csv_to_postgres' AIRFLOW_CTX_EXECUTION_DATE='2024-08-02T07:39:53.658874+00:00' AIRFLOW_CTX_TRY_NUMBER='1' AIRFLOW_CTX_DAG_RUN_ID='manual__2024-08-02T07:39:53.658874+00:00'
[2024-08-02T07:39:59.830+0000] {taskinstance.py:430} INFO - ::endgroup::
[2024-08-02T07:39:59.874+0000] {base.py:84} INFO - Using connection ID 'postgres' for task execution.
[2024-08-02T07:43:13.532+0000] {taskinstance.py:441} INFO - ::group::Post task execution logs
[2024-08-02T07:43:13.536+0000] {taskinstance.py:2905} ERROR - Task failed with exception
Traceback (most recent call last):
  File "/home/airflow/.local/lib/python3.12/site-packages/airflow/models/taskinstance.py", line 465, in _execute_task
    result = _execute_callable(context=context, **execute_callable_kwargs)
             ^^^^^^^^^^^^^^^^^^^^^^^^^^^^^^^^^^^^^^^^^^^^^^^^^^^^^^^^^^^^^
  File "/home/airflow/.local/lib/python3.12/site-packages/airflow/models/taskinstance.py", line 432, in _execute_callable
    return execute_callable(context=context, **execute_callable_kwargs)
           ^^^^^^^^^^^^^^^^^^^^^^^^^^^^^^^^^^^^^^^^^^^^^^^^^^^^^^^^^^^^
  File "/home/airflow/.local/lib/python3.12/site-packages/airflow/models/baseoperator.py", line 401, in wrapper
    return func(self, *args, **kwargs)
           ^^^^^^^^^^^^^^^^^^^^^^^^^^^
  File "/home/airflow/.local/lib/python3.12/site-packages/airflow/operators/python.py", line 235, in execute
    return_value = self.execute_callable()
                   ^^^^^^^^^^^^^^^^^^^^^^^
  File "/home/airflow/.local/lib/python3.12/site-packages/airflow/operators/python.py", line 252, in execute_callable
    return self.python_callable(*self.op_args, **self.op_kwargs)
           ^^^^^^^^^^^^^^^^^^^^^^^^^^^^^^^^^^^^^^^^^^^^^^^^^^^^^
  File "/opt/airflow/dags/ggsheet1.py", line 32, in load_csv_to_postgres
    conn = pg_hook.get_conn()
           ^^^^^^^^^^^^^^^^^^
  File "/home/airflow/.local/lib/python3.12/site-packages/airflow/providers/postgres/hooks/postgres.py", line 175, in get_conn
    self.conn = psycopg2.connect(**conn_args)
                ^^^^^^^^^^^^^^^^^^^^^^^^^^^^^
  File "/home/airflow/.local/lib/python3.12/site-packages/psycopg2/__init__.py", line 122, in connect
    conn = _connect(dsn, connection_factory=connection_factory, **kwasync)
           ^^^^^^^^^^^^^^^^^^^^^^^^^^^^^^^^^^^^^^^^^^^^^^^^^^^^^^^^^^^^^^^
psycopg2.OperationalError: connection to server at "172.19.0.3", port 5432 failed: Connection timed out
	Is the server running on that host and accepting TCP/IP connections?

[2024-08-02T07:43:13.561+0000] {taskinstance.py:1206} INFO - Marking task as UP_FOR_RETRY. dag_id=csv_to_postgres, task_id=load_csv_to_postgres, run_id=manual__2024-08-02T07:39:53.658874+00:00, execution_date=20240802T073953, start_date=20240802T073959, end_date=20240802T074313
[2024-08-02T07:43:13.584+0000] {standard_task_runner.py:110} ERROR - Failed to execute job 159 for task load_csv_to_postgres (connection to server at "172.19.0.3", port 5432 failed: Connection timed out
	Is the server running on that host and accepting TCP/IP connections?
; 121)
[2024-08-02T07:43:13.610+0000] {local_task_job_runner.py:243} INFO - Task exited with return code 1
[2024-08-02T07:43:13.627+0000] {taskinstance.py:3503} INFO - 0 downstream tasks scheduled from follow-on schedule check
[2024-08-02T07:43:13.630+0000] {local_task_job_runner.py:222} INFO - ::endgroup::
