[2024-07-13T15:08:32.105+0000] {taskinstance.py:1165} INFO - Dependencies all met for <TaskInstance: user_processing.process_user scheduled__2024-07-12T00:00:00+00:00 [queued]>
[2024-07-13T15:08:32.117+0000] {taskinstance.py:1165} INFO - Dependencies all met for <TaskInstance: user_processing.process_user scheduled__2024-07-12T00:00:00+00:00 [queued]>
[2024-07-13T15:08:32.118+0000] {taskinstance.py:1362} INFO - 
--------------------------------------------------------------------------------
[2024-07-13T15:08:32.119+0000] {taskinstance.py:1363} INFO - Starting attempt 1 of 1
[2024-07-13T15:08:32.119+0000] {taskinstance.py:1364} INFO - 
--------------------------------------------------------------------------------
[2024-07-13T15:08:32.137+0000] {taskinstance.py:1383} INFO - Executing <Task(PythonOperator): process_user> on 2024-07-12 00:00:00+00:00
[2024-07-13T15:08:32.144+0000] {standard_task_runner.py:55} INFO - Started process 3662 to run task
[2024-07-13T15:08:32.148+0000] {standard_task_runner.py:82} INFO - Running: ['***', 'tasks', 'run', 'user_processing', 'process_user', 'scheduled__2024-07-12T00:00:00+00:00', '--job-id', '16', '--raw', '--subdir', 'DAGS_FOLDER/user_processing.py', '--cfg-path', '/tmp/tmpb2i4af84']
[2024-07-13T15:08:32.151+0000] {standard_task_runner.py:83} INFO - Job 16: Subtask process_user
[2024-07-13T15:08:32.246+0000] {task_command.py:376} INFO - Running <TaskInstance: user_processing.process_user scheduled__2024-07-12T00:00:00+00:00 [running]> on host 87b219e3aacc
[2024-07-13T15:08:32.363+0000] {taskinstance.py:1592} INFO - Exporting the following env vars:
AIRFLOW_CTX_DAG_OWNER=***
AIRFLOW_CTX_DAG_ID=user_processing
AIRFLOW_CTX_TASK_ID=process_user
AIRFLOW_CTX_EXECUTION_DATE=2024-07-12T00:00:00+00:00
AIRFLOW_CTX_TRY_NUMBER=1
AIRFLOW_CTX_DAG_RUN_ID=scheduled__2024-07-12T00:00:00+00:00
[2024-07-13T15:08:32.379+0000] {taskinstance.py:1851} ERROR - Task failed with exception
Traceback (most recent call last):
  File "/home/airflow/.local/lib/python3.7/site-packages/airflow/operators/python.py", line 175, in execute
    return_value = self.execute_callable()
  File "/home/airflow/.local/lib/python3.7/site-packages/airflow/operators/python.py", line 193, in execute_callable
    return self.python_callable(*self.op_args, **self.op_kwargs)
  File "/opt/airflow/dags/user_processing.py", line 21, in _process_user
    'password': user['login']['password]'],
KeyError: 'password]'
[2024-07-13T15:08:32.402+0000] {taskinstance.py:1406} INFO - Marking task as FAILED. dag_id=user_processing, task_id=process_user, execution_date=20240712T000000, start_date=20240713T150832, end_date=20240713T150832
[2024-07-13T15:08:32.417+0000] {standard_task_runner.py:105} ERROR - Failed to execute job 16 for task process_user ('password]'; 3662)
[2024-07-13T15:08:32.440+0000] {local_task_job.py:164} INFO - Task exited with return code 1
[2024-07-13T15:08:32.462+0000] {local_task_job.py:273} INFO - 0 downstream tasks scheduled from follow-on schedule check
