[2024-07-29T15:20:32.057+0000] {local_task_job_runner.py:120} INFO - ::group::Pre task execution logs
[2024-07-29T15:20:32.098+0000] {taskinstance.py:2076} INFO - Dependencies all met for dep_context=non-requeueable deps ti=<TaskInstance: csv_to_postgres.load_csv_to_postgres manual__2024-07-29T15:20:29.625336+00:00 [queued]>
[2024-07-29T15:20:32.111+0000] {taskinstance.py:2076} INFO - Dependencies all met for dep_context=requeueable deps ti=<TaskInstance: csv_to_postgres.load_csv_to_postgres manual__2024-07-29T15:20:29.625336+00:00 [queued]>
[2024-07-29T15:20:32.113+0000] {taskinstance.py:2306} INFO - Starting attempt 1 of 2
[2024-07-29T15:20:32.143+0000] {taskinstance.py:2330} INFO - Executing <Task(PythonOperator): load_csv_to_postgres> on 2024-07-29 15:20:29.625336+00:00
[2024-07-29T15:20:32.156+0000] {warnings.py:112} WARNING - /home/***/.local/lib/python3.12/site-packages/***/task/task_runner/standard_task_runner.py:62: DeprecationWarning: This process (pid=946) is multi-threaded, use of fork() may lead to deadlocks in the child.
  pid = os.fork()

[2024-07-29T15:20:32.159+0000] {standard_task_runner.py:90} INFO - Running: ['***', 'tasks', 'run', 'csv_to_postgres', 'load_csv_to_postgres', 'manual__2024-07-29T15:20:29.625336+00:00', '--job-id', '134', '--raw', '--subdir', 'DAGS_FOLDER/csv.py', '--cfg-path', '/tmp/tmp5snmdgw0']
[2024-07-29T15:20:32.160+0000] {standard_task_runner.py:64} INFO - Started process 948 to run task
[2024-07-29T15:20:32.161+0000] {standard_task_runner.py:91} INFO - Job 134: Subtask load_csv_to_postgres
[2024-07-29T15:20:32.238+0000] {task_command.py:426} INFO - Running <TaskInstance: csv_to_postgres.load_csv_to_postgres manual__2024-07-29T15:20:29.625336+00:00 [running]> on host 9dd1e705964b
[2024-07-29T15:20:32.371+0000] {taskinstance.py:2648} INFO - Exporting env vars: AIRFLOW_CTX_DAG_OWNER='***' AIRFLOW_CTX_DAG_ID='csv_to_postgres' AIRFLOW_CTX_TASK_ID='load_csv_to_postgres' AIRFLOW_CTX_EXECUTION_DATE='2024-07-29T15:20:29.625336+00:00' AIRFLOW_CTX_TRY_NUMBER='1' AIRFLOW_CTX_DAG_RUN_ID='manual__2024-07-29T15:20:29.625336+00:00'
[2024-07-29T15:20:32.374+0000] {taskinstance.py:430} INFO - ::endgroup::
[2024-07-29T15:20:32.384+0000] {base.py:84} INFO - Using connection ID 'postgres' for task execution.
[2024-07-29T15:20:32.389+0000] {taskinstance.py:441} INFO - ::group::Post task execution logs
[2024-07-29T15:20:32.390+0000] {taskinstance.py:2905} ERROR - Task failed with exception
Traceback (most recent call last):
  File "/home/airflow/.local/lib/python3.12/site-packages/airflow/models/taskinstance.py", line 465, in _execute_task
    result = _execute_callable(context=context, **execute_callable_kwargs)
             ^^^^^^^^^^^^^^^^^^^^^^^^^^^^^^^^^^^^^^^^^^^^^^^^^^^^^^^^^^^^^
  File "/home/airflow/.local/lib/python3.12/site-packages/airflow/models/taskinstance.py", line 432, in _execute_callable
    return execute_callable(context=context, **execute_callable_kwargs)
           ^^^^^^^^^^^^^^^^^^^^^^^^^^^^^^^^^^^^^^^^^^^^^^^^^^^^^^^^^^^^
  File "/home/airflow/.local/lib/python3.12/site-packages/airflow/models/baseoperator.py", line 401, in wrapper
    return func(self, *args, **kwargs)
           ^^^^^^^^^^^^^^^^^^^^^^^^^^^
  File "/home/airflow/.local/lib/python3.12/site-packages/airflow/operators/python.py", line 235, in execute
    return_value = self.execute_callable()
                   ^^^^^^^^^^^^^^^^^^^^^^^
  File "/home/airflow/.local/lib/python3.12/site-packages/airflow/operators/python.py", line 252, in execute_callable
    return self.python_callable(*self.op_args, **self.op_kwargs)
           ^^^^^^^^^^^^^^^^^^^^^^^^^^^^^^^^^^^^^^^^^^^^^^^^^^^^^
  File "/opt/airflow/dags/csv.py", line 36, in load_csv_to_postgres
    for file_name in os.listdir(CSV_FOLDER):
                     ^^^^^^^^^^^^^^^^^^^^^^
FileNotFoundError: [Errno 2] No such file or directory: 'D:\\intern_de\\csv'
[2024-07-29T15:20:32.406+0000] {taskinstance.py:1206} INFO - Marking task as UP_FOR_RETRY. dag_id=csv_to_postgres, task_id=load_csv_to_postgres, run_id=manual__2024-07-29T15:20:29.625336+00:00, execution_date=20240729T152029, start_date=20240729T152032, end_date=20240729T152032
[2024-07-29T15:20:32.426+0000] {standard_task_runner.py:110} ERROR - Failed to execute job 134 for task load_csv_to_postgres ([Errno 2] No such file or directory: 'D:\\intern_de\\csv'; 948)
[2024-07-29T15:20:32.456+0000] {local_task_job_runner.py:243} INFO - Task exited with return code 1
[2024-07-29T15:20:32.475+0000] {taskinstance.py:3503} INFO - 0 downstream tasks scheduled from follow-on schedule check
[2024-07-29T15:20:32.479+0000] {local_task_job_runner.py:222} INFO - ::endgroup::
