[2024-07-27T02:38:41.005+0000] {local_task_job_runner.py:120} INFO - ::group::Pre task execution logs
[2024-07-27T02:38:41.032+0000] {taskinstance.py:2076} INFO - Dependencies all met for dep_context=non-requeueable deps ti=<TaskInstance: csv_to_postgres.load_csv_to_postgres scheduled__2024-07-26T00:00:00+00:00 [queued]>
[2024-07-27T02:38:41.040+0000] {taskinstance.py:2076} INFO - Dependencies all met for dep_context=requeueable deps ti=<TaskInstance: csv_to_postgres.load_csv_to_postgres scheduled__2024-07-26T00:00:00+00:00 [queued]>
[2024-07-27T02:38:41.041+0000] {taskinstance.py:2306} INFO - Starting attempt 1 of 2
[2024-07-27T02:38:41.056+0000] {taskinstance.py:2330} INFO - Executing <Task(PythonOperator): load_csv_to_postgres> on 2024-07-26 00:00:00+00:00
[2024-07-27T02:38:41.065+0000] {warnings.py:112} WARNING - /home/***/.local/lib/python3.12/site-packages/***/task/task_runner/standard_task_runner.py:62: DeprecationWarning: This process (pid=362) is multi-threaded, use of fork() may lead to deadlocks in the child.
  pid = os.fork()

[2024-07-27T02:38:41.067+0000] {standard_task_runner.py:64} INFO - Started process 366 to run task
[2024-07-27T02:38:41.067+0000] {standard_task_runner.py:90} INFO - Running: ['***', 'tasks', 'run', 'csv_to_postgres', 'load_csv_to_postgres', 'scheduled__2024-07-26T00:00:00+00:00', '--job-id', '119', '--raw', '--subdir', 'DAGS_FOLDER/ggsheet1.py', '--cfg-path', '/tmp/tmpzhw3v8j2']
[2024-07-27T02:38:41.068+0000] {standard_task_runner.py:91} INFO - Job 119: Subtask load_csv_to_postgres
[2024-07-27T02:38:41.124+0000] {task_command.py:426} INFO - Running <TaskInstance: csv_to_postgres.load_csv_to_postgres scheduled__2024-07-26T00:00:00+00:00 [running]> on host 9dd1e705964b
[2024-07-27T02:38:41.221+0000] {taskinstance.py:2648} INFO - Exporting env vars: AIRFLOW_CTX_DAG_OWNER='***' AIRFLOW_CTX_DAG_ID='csv_to_postgres' AIRFLOW_CTX_TASK_ID='load_csv_to_postgres' AIRFLOW_CTX_EXECUTION_DATE='2024-07-26T00:00:00+00:00' AIRFLOW_CTX_TRY_NUMBER='1' AIRFLOW_CTX_DAG_RUN_ID='scheduled__2024-07-26T00:00:00+00:00'
[2024-07-27T02:38:41.222+0000] {taskinstance.py:430} INFO - ::endgroup::
[2024-07-27T02:38:41.232+0000] {taskinstance.py:441} INFO - ::group::Post task execution logs
[2024-07-27T02:38:41.243+0000] {taskinstance.py:2905} ERROR - Task failed with exception
Traceback (most recent call last):
  File "/home/airflow/.local/lib/python3.12/site-packages/airflow/models/taskinstance.py", line 465, in _execute_task
    result = _execute_callable(context=context, **execute_callable_kwargs)
             ^^^^^^^^^^^^^^^^^^^^^^^^^^^^^^^^^^^^^^^^^^^^^^^^^^^^^^^^^^^^^
  File "/home/airflow/.local/lib/python3.12/site-packages/airflow/models/taskinstance.py", line 432, in _execute_callable
    return execute_callable(context=context, **execute_callable_kwargs)
           ^^^^^^^^^^^^^^^^^^^^^^^^^^^^^^^^^^^^^^^^^^^^^^^^^^^^^^^^^^^^
  File "/home/airflow/.local/lib/python3.12/site-packages/airflow/models/baseoperator.py", line 401, in wrapper
    return func(self, *args, **kwargs)
           ^^^^^^^^^^^^^^^^^^^^^^^^^^^
  File "/home/airflow/.local/lib/python3.12/site-packages/airflow/operators/python.py", line 235, in execute
    return_value = self.execute_callable()
                   ^^^^^^^^^^^^^^^^^^^^^^^
  File "/home/airflow/.local/lib/python3.12/site-packages/airflow/operators/python.py", line 252, in execute_callable
    return self.python_callable(*self.op_args, **self.op_kwargs)
           ^^^^^^^^^^^^^^^^^^^^^^^^^^^^^^^^^^^^^^^^^^^^^^^^^^^^^
  File "/opt/airflow/dags/ggsheet1.py", line 32, in load_csv_to_postgres
    conn = pg_hook.get_conn()
           ^^^^^^^^^^^^^^^^^^
  File "/home/airflow/.local/lib/python3.12/site-packages/airflow/providers/postgres/hooks/postgres.py", line 145, in get_conn
    conn = deepcopy(self.connection or self.get_connection(conn_id))
                                       ^^^^^^^^^^^^^^^^^^^^^^^^^^^^
  File "/home/airflow/.local/lib/python3.12/site-packages/airflow/hooks/base.py", line 83, in get_connection
    conn = Connection.get_connection_from_secrets(conn_id)
           ^^^^^^^^^^^^^^^^^^^^^^^^^^^^^^^^^^^^^^^^^^^^^^^
  File "/home/airflow/.local/lib/python3.12/site-packages/airflow/models/connection.py", line 519, in get_connection_from_secrets
    raise AirflowNotFoundException(f"The conn_id `{conn_id}` isn't defined")
airflow.exceptions.AirflowNotFoundException: The conn_id `postgres` isn't defined
[2024-07-27T02:38:41.252+0000] {taskinstance.py:1206} INFO - Marking task as UP_FOR_RETRY. dag_id=csv_to_postgres, task_id=load_csv_to_postgres, run_id=scheduled__2024-07-26T00:00:00+00:00, execution_date=20240726T000000, start_date=20240727T023841, end_date=20240727T023841
[2024-07-27T02:38:41.268+0000] {standard_task_runner.py:110} ERROR - Failed to execute job 119 for task load_csv_to_postgres (The conn_id `postgres` isn't defined; 366)
[2024-07-27T02:38:41.282+0000] {local_task_job_runner.py:243} INFO - Task exited with return code 1
[2024-07-27T02:38:41.299+0000] {taskinstance.py:3503} INFO - 0 downstream tasks scheduled from follow-on schedule check
[2024-07-27T02:38:41.305+0000] {local_task_job_runner.py:222} INFO - ::endgroup::
