[2024-08-09T06:46:24.100+0000] {local_task_job_runner.py:120} INFO - ::group::Pre task execution logs
[2024-08-09T06:46:24.121+0000] {taskinstance.py:2076} INFO - Dependencies all met for dep_context=non-requeueable deps ti=<TaskInstance: etl_mysql.etl_task scheduled__2024-08-08T00:00:00+00:00 [queued]>
[2024-08-09T06:46:24.129+0000] {taskinstance.py:2076} INFO - Dependencies all met for dep_context=requeueable deps ti=<TaskInstance: etl_mysql.etl_task scheduled__2024-08-08T00:00:00+00:00 [queued]>
[2024-08-09T06:46:24.130+0000] {taskinstance.py:2306} INFO - Starting attempt 2 of 2
[2024-08-09T06:46:24.145+0000] {taskinstance.py:2330} INFO - Executing <Task(PythonOperator): etl_task> on 2024-08-08 00:00:00+00:00
[2024-08-09T06:46:24.153+0000] {warnings.py:112} WARNING - /home/***/.local/lib/python3.12/site-packages/***/task/task_runner/standard_task_runner.py:62: DeprecationWarning: This process (pid=103) is multi-threaded, use of fork() may lead to deadlocks in the child.
  pid = os.fork()

[2024-08-09T06:46:24.155+0000] {standard_task_runner.py:64} INFO - Started process 105 to run task
[2024-08-09T06:46:24.156+0000] {standard_task_runner.py:90} INFO - Running: ['***', 'tasks', 'run', 'etl_mysql', 'etl_task', 'scheduled__2024-08-08T00:00:00+00:00', '--job-id', '199', '--raw', '--subdir', 'DAGS_FOLDER/etl_mysql.py', '--cfg-path', '/tmp/tmp7mhm3l_y']
[2024-08-09T06:46:24.159+0000] {standard_task_runner.py:91} INFO - Job 199: Subtask etl_task
[2024-08-09T06:46:24.209+0000] {task_command.py:426} INFO - Running <TaskInstance: etl_mysql.etl_task scheduled__2024-08-08T00:00:00+00:00 [running]> on host c6a41f5817de
[2024-08-09T06:46:24.306+0000] {taskinstance.py:2648} INFO - Exporting env vars: AIRFLOW_CTX_DAG_OWNER='***' AIRFLOW_CTX_DAG_ID='etl_mysql' AIRFLOW_CTX_TASK_ID='etl_task' AIRFLOW_CTX_EXECUTION_DATE='2024-08-08T00:00:00+00:00' AIRFLOW_CTX_TRY_NUMBER='2' AIRFLOW_CTX_DAG_RUN_ID='scheduled__2024-08-08T00:00:00+00:00'
[2024-08-09T06:46:24.308+0000] {taskinstance.py:430} INFO - ::endgroup::
[2024-08-09T06:46:58.433+0000] {taskinstance.py:441} INFO - ::group::Post task execution logs
[2024-08-09T06:46:58.434+0000] {taskinstance.py:2905} ERROR - Task failed with exception
Traceback (most recent call last):
  File "/home/airflow/.local/lib/python3.12/site-packages/mysql/connector/connection_cext.py", line 334, in _open_connection
    self._cmysql.connect(**cnx_kwargs)
_mysql_connector.MySQLInterfaceError: Unknown MySQL server host 'son-mysql' (-2)

The above exception was the direct cause of the following exception:

Traceback (most recent call last):
  File "/home/airflow/.local/lib/python3.12/site-packages/airflow/models/taskinstance.py", line 465, in _execute_task
    result = _execute_callable(context=context, **execute_callable_kwargs)
             ^^^^^^^^^^^^^^^^^^^^^^^^^^^^^^^^^^^^^^^^^^^^^^^^^^^^^^^^^^^^^
  File "/home/airflow/.local/lib/python3.12/site-packages/airflow/models/taskinstance.py", line 432, in _execute_callable
    return execute_callable(context=context, **execute_callable_kwargs)
           ^^^^^^^^^^^^^^^^^^^^^^^^^^^^^^^^^^^^^^^^^^^^^^^^^^^^^^^^^^^^
  File "/home/airflow/.local/lib/python3.12/site-packages/airflow/models/baseoperator.py", line 401, in wrapper
    return func(self, *args, **kwargs)
           ^^^^^^^^^^^^^^^^^^^^^^^^^^^
  File "/home/airflow/.local/lib/python3.12/site-packages/airflow/operators/python.py", line 235, in execute
    return_value = self.execute_callable()
                   ^^^^^^^^^^^^^^^^^^^^^^^
  File "/home/airflow/.local/lib/python3.12/site-packages/airflow/operators/python.py", line 252, in execute_callable
    return self.python_callable(*self.op_args, **self.op_kwargs)
           ^^^^^^^^^^^^^^^^^^^^^^^^^^^^^^^^^^^^^^^^^^^^^^^^^^^^^
  File "/opt/airflow/dags/etl_mysql.py", line 50, in etl
    target_conn = mysql.connector.connect(
                  ^^^^^^^^^^^^^^^^^^^^^^^^
  File "/home/airflow/.local/lib/python3.12/site-packages/mysql/connector/pooling.py", line 322, in connect
    return CMySQLConnection(*args, **kwargs)
           ^^^^^^^^^^^^^^^^^^^^^^^^^^^^^^^^^
  File "/home/airflow/.local/lib/python3.12/site-packages/mysql/connector/connection_cext.py", line 151, in __init__
    self.connect(**kwargs)
  File "/home/airflow/.local/lib/python3.12/site-packages/mysql/connector/abstracts.py", line 1399, in connect
    self._open_connection()
  File "/home/airflow/.local/lib/python3.12/site-packages/mysql/connector/connection_cext.py", line 339, in _open_connection
    raise get_mysql_exception(
mysql.connector.errors.DatabaseError: 2005 (HY000): Unknown MySQL server host 'son-mysql' (-2)
[2024-08-09T06:46:58.459+0000] {taskinstance.py:1206} INFO - Marking task as FAILED. dag_id=etl_mysql, task_id=etl_task, run_id=scheduled__2024-08-08T00:00:00+00:00, execution_date=20240808T000000, start_date=20240809T064624, end_date=20240809T064658
[2024-08-09T06:46:58.479+0000] {standard_task_runner.py:110} ERROR - Failed to execute job 199 for task etl_task (2005 (HY000): Unknown MySQL server host 'son-mysql' (-2); 105)
[2024-08-09T06:46:58.494+0000] {local_task_job_runner.py:243} INFO - Task exited with return code 1
[2024-08-09T06:46:58.515+0000] {taskinstance.py:3503} INFO - 0 downstream tasks scheduled from follow-on schedule check
[2024-08-09T06:46:58.519+0000] {local_task_job_runner.py:222} INFO - ::endgroup::
